# Nicolas Ternisien <nicolas@bureau-cornavin.com>, 2016.
# Eric Bischoff <eric@bureau-cornavin.com>, 2016.
msgid ""
msgstr ""
"Project-Id-Version: univention-management-console-module-diagnostic\n"
"Report-Msgid-Bugs-To: packages@univention.de\n"
"POT-Creation-Date: 2021-11-03 17:54+0100\n"
"PO-Revision-Date: 2016-07-10 14:04+0100\n"
"Last-Translator: Eric Bischoff <eric@bureau-cornavin.com>\n"
"Language-Team: French <fr@bureau-cornavin.com>\n"
"Language: fr\n"
"MIME-Version: 1.0\n"
"Content-Type: text/plain; charset=UTF-8\n"
"Content-Transfer-Encoding: 8bit\n"
"Plural-Forms: nplurals=2; plural=(n > 1);\n"
"X-Generator: Lokalize 2.0\n"

#: umc/python/diagnostic/plugins/21_check_join_status.py:55
msgid ""
"\"univention-check-join-status\" returned a problem with the domain join."
msgstr ""

#: umc/python/diagnostic/plugins/56_univention_types.py:57
#, python-format
msgid "%d objects should be \"%s\""
msgstr ""

#: umc/python/diagnostic/plugins/11_nameserver.py:15
#, python-format
msgid "%d of the configured nameservers are not responding to DNS queries."
msgstr "%d des serveurs de noms configurés ne répondent pas aux requêtes DNS."

#: umc/python/diagnostic/plugins/30_disk_usage.py:121
#, python-format
msgid "- Disk for mountpoint %(mp)s is %(pc)s%% full."
msgstr ""

#: umc/python/diagnostic/plugins/11_nameserver.py:48
msgid "A timeout occurred while reaching the nameserver (is it online?)."
msgstr "Délai dépassé lors de l'accès au serveur de noms (est-il connecté ?)."

#: umc/python/diagnostic/plugins/52_mail_acl_sync.py:94
msgid "ACL right for group {id!r} is {udm!r} in UDM, but {imap!r} in IMAP."
msgstr ""

#: umc/python/diagnostic/plugins/52_mail_acl_sync.py:88
msgid "ACL right for user {id!r} is {udm!r} in UDM, but {imap!r} in IMAP."
msgstr ""

#: umc/python/diagnostic/plugins/58_check_memberOf.py:45
msgid "Activate the memberOf LDAP overlay"
msgstr ""

#: umc/python/diagnostic/plugins/22_kdc_service.py:370
msgid "Add lo to samba/interfaces"
msgstr ""

#: umc/python/diagnostic/plugins/32_security_limits.py:30
msgid "Adjust to suggested limits"
msgstr "Ajuster aux limites suggérées"

#: umc/python/diagnostic/plugins/44_well_known_sid_check.py:46
msgid "All SIDs exist and names are consistent."
msgstr ""

#: umc/python/diagnostic/plugins/02_certificate_check.py:52
msgid "All SSL certificates valid."
msgstr ""

#: umc/python/diagnostic/plugins/31_file_permissions.py:49
#: umc/python/diagnostic/plugins/54_sources_list_check.py:44
msgid "All files ok."
msgstr ""

#: umc/python/diagnostic/plugins/52_mail_acl_sync.py:49
msgid "All shared folder ACLs are in sync with UDM."
msgstr ""

#: umc/python/diagnostic/plugins/00_check_server_password.py:161
msgid ""
"Authentication against the Primary LDAP failed with the machine password."
msgstr ""

#: umc/python/diagnostic/plugins/00_check_server_password.py:157
msgid "Authentication against the local LDAP failed with the machine password."
msgstr ""

#: umc/python/diagnostic/plugins/00_check_server_password.py:53
msgid "Authentication with machine password against LDAP successful."
msgstr ""

#: umc/python/diagnostic/plugins/00_check_server_password.py:116
msgid "Calling /usr/lib/univention-server/server_password_change failed."
msgstr ""

#: umc/python/diagnostic/plugins/02_certificate_check.py:75
msgid "Certificate {path!r} will expire in {days} days."
msgstr ""

#: umc/python/diagnostic/plugins/45_heimdal_on_samba4_dc.py:45
msgid "Check Heimdal KDC on Samba 4 DC"
msgstr ""

#: umc/python/diagnostic/plugins/52_mail_acl_sync.py:48
msgid "Check IMAP shared folder ACLs"
msgstr ""

#: umc/python/diagnostic/plugins/58_check_memberOf.py:39
msgid "Check LDAP attribute memberOf"
msgstr ""

#: umc/python/diagnostic/plugins/41_samba_tool_showrepl.py:53
msgid "Check Samba replication status for errors"
msgstr ""

#: umc/python/diagnostic/plugins/54_sources_list_check.py:43
msgid "Check errors in sources.list files"
msgstr ""

#: umc/python/diagnostic/plugins/31_file_permissions.py:48
msgid "Check file permissions"
msgstr ""

#: umc/python/diagnostic/plugins/50_check_ucr_templates.py:41
msgid "Check for modified UCR templates"
msgstr ""

#: umc/python/diagnostic/plugins/03_check_notifier_replication.py:41
msgid "Check for problems with UDN replication"
msgstr ""

#: umc/python/diagnostic/plugins/30_disk_usage.py:42
msgid "Check free disk space"
msgstr ""

#: umc/python/diagnostic/plugins/51_hostname_check.py:42
msgid "Check hostname RFC compliance"
msgstr ""

#: umc/python/diagnostic/plugins/21_check_join_status.py:40
msgid "Check join status"
msgstr ""

#: umc/python/diagnostic/plugins/46_kerberos_ddns_update.py:45
msgid "Check kerberos authenticated DNS updates"
msgstr ""

#: umc/python/diagnostic/plugins/40_samba_tool_dbcheck.py:39
msgid "Check local AD database for errors"
msgstr ""

#: umc/python/diagnostic/plugins/00_check_server_password.py:52
msgid "Check machine password"
msgstr ""

#: umc/python/diagnostic/plugins/20_check_nameservers.py:49
msgid "Check nameserver entries on DNS zones"
msgstr ""

#: umc/python/diagnostic/plugins/59_ldap_server_name.py:13
msgid "Check primary LDAP server"
msgstr ""

#: umc/python/diagnostic/plugins/23_check_update_sites.py:42
msgid "Check resolving repository servers"
msgstr ""

#: umc/python/diagnostic/plugins/02_certificate_check.py:51
msgid "Check validity of SSL certificates"
msgstr ""

#: umc/python/diagnostic/plugins/44_well_known_sid_check.py:45
msgid "Check well known SIDs"
msgstr ""

#: umc/python/diagnostic/plugins/58_check_memberOf.py:40
msgid "Check whether the LDAP overlay memberOf is locally activated."
msgstr ""

#: umc/python/diagnostic/plugins/59_ldap_server_name.py:59
msgid "Deactivate test"
msgstr ""

#: umc/python/diagnostic/plugins/30_disk_usage.py:43
msgid "Enough free disk space available."
msgstr ""

#: umc/python/diagnostic/plugins/03_check_notifier_replication.py:72
msgid "Error retrieving notifier ID from the UDN."
msgstr ""

#: umc/python/diagnostic/plugins/50_check_ucr_templates.py:52
msgid "Errors found by `univention-check-templates`."
msgstr ""

#: umc/python/diagnostic/plugins/46_kerberos_ddns_update.py:164
msgid "Errors occurred while running `kinit` or `nsupdate`."
msgstr ""

#: umc/python/diagnostic/plugins/31_file_permissions.py:60
msgid "File {path!r} does not exist."
msgstr ""

#: umc/python/diagnostic/plugins/31_file_permissions.py:81
msgid "File {path!r} has mode {actual:o}, {expected:o} was expected."
msgstr ""

#: umc/python/diagnostic/plugins/31_file_permissions.py:70
msgid "File {path!r} has owner {actual!r} while {expected!r} was expected."
msgstr ""

#: umc/python/diagnostic/plugins/00_check_server_password.py:152
msgid "Fix machine password"
msgstr ""

#: umc/python/diagnostic/plugins/52_mail_acl_sync.py:234
msgid ""
"Found differences in the ACLs for IMAP shared folders between UDM and IMAP."
msgstr ""

#: umc/python/diagnostic/plugins/20_check_nameservers.py:219
msgid "Found errors in the nameserver entries of the following zones."
msgstr ""

#: umc/python/diagnostic/plugins/54_sources_list_check.py:75
msgid "Found exception in {path!r}: {exception}"
msgstr ""

#: umc/python/diagnostic/plugins/02_certificate_check.py:92
msgid "Found expired certificate {path!r}."
msgstr ""

#: umc/python/diagnostic/plugins/20_check_nameservers.py:80
#, python-brace-format
msgid "Found illegal alias record (CNAME record) for nameserver {ns}."
msgstr ""

#: umc/python/diagnostic/plugins/02_certificate_check.py:105
msgid "Found invalid certificate {path!r}."
msgstr ""

#: umc/python/diagnostic/plugins/02_certificate_check.py:103
msgid ""
"Found invalid certificate {path!r}:\n"
"{message}"
msgstr ""

#: umc/python/diagnostic/plugins/02_certificate_check.py:114
msgid "Found malformed certificate {path!r}."
msgstr ""

#: umc/python/diagnostic/plugins/20_check_nameservers.py:74
#, python-brace-format
msgid "Found no host record (A/AAAA record) for nameserver {ns}."
msgstr ""

#: umc/python/diagnostic/plugins/02_certificate_check.py:86
msgid "Found not yet valid certificate {path!r}."
msgstr ""

#: umc/python/diagnostic/plugins/43_connectors4_rejects.py:105
#, python-brace-format
msgid ""
"Found {ucs} UCS rejects and {s4} S4 rejects. See {{sdb}} for more "
"information."
msgstr ""

#: umc/python/diagnostic/plugins/10_gateway.py:11
msgid "Gateway is not reachable"
msgstr "La passerelle n'est pas accessible"

#: umc/python/diagnostic/plugins/01_ssh_connection.py:67
msgid "Host key for server does not match"
msgstr "La clé d'hôte pour ce serveur ne correspond pas"

#: umc/python/diagnostic/plugins/11_nameserver.py:17
msgid ""
"If the problem persists make sure the nameserver is connected to the network "
"and the forwarders are able to reach the internet (www.univention.de)."
msgstr ""
"Si le problème persiste, veuillez vous assurer que le serveur de noms est "
"connecté au réseau et que les transmetteurs (forwarders) peuvent accéder à "
"Internet (www.univention.de)."

#: umc/python/diagnostic/plugins/10_gateway.py:14
msgid "If these settings are correct the problem relies in the gateway itself:"
msgstr ""
"Si ces réglages sont corrects, le problème provient de la passerelle elle-"
"même :"

#: umc/python/diagnostic/plugins/20_check_nameservers.py:223
#, python-brace-format
msgid "In forward zone {name} (see {{{link}}}):"
msgstr ""

#: umc/python/diagnostic/plugins/52_mail_acl_sync.py:242
#, python-brace-format
msgid "In mail folder {name} (see {{udm:mail/mail}}):"
msgstr ""

#: umc/python/diagnostic/plugins/20_check_nameservers.py:224
#, python-brace-format
msgid "In reverse zone {name} (see {{{link}}}):"
msgstr ""

#: umc/python/diagnostic/plugins/41_samba_tool_showrepl.py:129
msgid "Inbound {nc!r}: error during DRS replication from {source} ({estring})"
msgstr ""

#: umc/python/diagnostic/plugins/32_security_limits.py:19
#, python-brace-format
msgid ""
"It is suggested to increase the security limits either manually by using "
"{ucr} or to automatically adjust them to the suggested limits:"
msgstr ""
"Il est conseillé d'augmenter les limites de sécurité manuellement en "
"utilisant {ucr} ou de les ajuster automatiquement aux limites proposées :"

#: umc/python/diagnostic/plugins/22_kdc_service.py:57
msgid "KDC service check"
msgstr ""

#: umc/python/diagnostic/plugins/56_univention_types.py:13
msgid "LDAP objects"
msgstr ""

#: umc/python/diagnostic/plugins/60_old_schema_registration.py:15
msgid "LDAP schema files are not properly registered"
msgstr ""

#: umc/python/diagnostic/plugins/01_ssh_connection.py:72
#, python-format
msgid ""
"Login to the remote server with the uid %(uid)s and the password from /etc/"
"machine.secret failed. "
msgstr ""
"Échec de la connexion au serveur distant avec l'UID %(uid)s et le mot de "
"passe issu de « /etc/machine.secret ». "

#: umc/python/diagnostic/plugins/01_ssh_connection.py:71
msgid "Machine authentication failed"
msgstr "Échec de l'authentification à la machine"

#: umc/python/diagnostic/plugins/52_mail_acl_sync.py:63
msgid "Mail folder {folder!r} does not exist in IMAP."
msgstr ""

#: umc/python/diagnostic/plugins/10_gateway.py:15
msgid "Make sure the hardware of the gateway device is working properly."
msgstr ""
"Veuillez vous assurer que l'équipement de passerelle fonctionne "
"convenablement."

#: umc/python/diagnostic/plugins/21_check_join_status.py:45
msgid "Manual: Analysis of listener/notifier problems"
msgstr ""

#: umc/python/diagnostic/plugins/57_univention_server_role_windows.py:102
#: umc/python/diagnostic/plugins/56_univention_types.py:60
#, python-format
msgid "Migrate %d LDAP objects"
msgstr ""

#: umc/python/diagnostic/plugins/55_user_migration.py:31
msgid "Migrate user objects"
msgstr ""

#: umc/python/diagnostic/plugins/53_package_status.py:15
msgid ""
"More information about the cause can be gained by executing \"dpkg --audit\"."
msgstr ""
"Des informations complémentaires sur l'origine du problème peuvent être "
"obtenues en exécutant « dpkg --audit »."

#: umc/python/diagnostic/plugins/52_mail_acl_sync.py:75
msgid "Multiple ACL entries for {id!r} in UDM."
msgstr ""

#: umc/python/diagnostic/plugins/11_nameserver.py:13
msgid "Nameserver(s) are not responsive"
msgstr "Le ou les serveurs de noms ne sont pas réactifs"

#: umc/python/diagnostic/plugins/43_connectors4_rejects.py:43
msgid "No S4 Connector rejects were found."
msgstr ""

#: umc/python/diagnostic/plugins/40_samba_tool_dbcheck.py:40
#: umc/python/diagnostic/plugins/41_samba_tool_showrepl.py:54
msgid "No errors found."
msgstr ""

#: umc/python/diagnostic/plugins/46_kerberos_ddns_update.py:46
msgid "No errors occurred."
msgstr ""

#: umc/python/diagnostic/plugins/51_hostname_check.py:43
msgid "No non-compliant hostnames found."
msgstr ""

#: umc/python/diagnostic/plugins/03_check_notifier_replication.py:42
msgid "No problems found with UDN replication."
msgstr ""

#: umc/python/diagnostic/plugins/50_check_ucr_templates.py:42
msgid "No problems found with modified UCR templates"
msgstr ""

#: umc/python/diagnostic/plugins/23_check_update_sites.py:43
msgid "No problems were found while resolving update repositories."
msgstr ""

#: umc/python/diagnostic/plugins/22_kdc_service.py:377
msgid "No reachable KDCs were found."
msgstr ""

#: umc/python/diagnostic/plugins/44_well_known_sid_check.py:65
msgid "No user or group with SID {sid} found, expected {expected!r}."
msgstr ""

#: umc/python/diagnostic/plugins/00_check_server_password.py:170
msgid ""
"Note that password rotation is disabled via the UCR variable server/password/"
"change."
msgstr ""

#: umc/python/diagnostic/plugins/00_check_server_password.py:171
msgid "Note that server/password/interval is set to {}."
msgstr ""

#: umc/python/diagnostic/plugins/57_univention_server_role_windows.py:95
#, python-format
msgid "Number of objects that should be marked as \"%s\": %d"
msgstr ""

#: umc/python/diagnostic/plugins/57_univention_server_role_windows.py:97
#, python-format
msgid ""
"Number of unspecific Windows computer objects with inconsistent "
"univentionObjectType: %d (Can't fix this automatically)"
msgstr ""

#: umc/python/diagnostic/plugins/57_univention_server_role_windows.py:45
msgid ""
"Objects that implicitly satisfy the criteria of a Univention Object but lack "
"this attribute should be migrated."
msgstr ""

#: umc/python/diagnostic/plugins/56_univention_types.py:16
msgid ""
"Objects that implicitly satisfy the standards of a Univention Object but "
"lack this attribute should be migrated."
msgstr ""

#: umc/python/diagnostic/plugins/60_old_schema_registration.py:17
msgid ""
"Old packages and Apps registered schema files by copying the files locally "
"into a certain directory."
msgstr ""

#: umc/python/diagnostic/plugins/41_samba_tool_showrepl.py:136
msgid "Outbound {nc!r}: error during DRS replication to {source} ({estring})"
msgstr ""

#: umc/python/diagnostic/plugins/40_samba_tool_dbcheck.py:53
#, python-brace-format
msgid "Output of `{cmd}`:"
msgstr ""

#: umc/python/diagnostic/plugins/53_package_status.py:11
msgid "Package status corrupt"
msgstr "Corruption de l'état du paquetage"

#: umc/python/diagnostic/plugins/01_ssh_connection.py:73
msgid ""
"Please check /var/log/auth.log on the remote server for further information."
msgstr ""
"Veuillez vérifier « /var/log/auth.log » sur le serveur distant pour plus "
"d'informations."

#: umc/python/diagnostic/plugins/54_sources_list_check.py:101
msgid "Please check the files for more details."
msgstr ""

#: umc/python/diagnostic/plugins/11_nameserver.py:16
msgid ""
"Please make sure the DNS settings in the {setup:network} are correctly set "
"up."
msgstr ""
"Veuillez vous assurer que les réglages DNS dans {setup:network} sont "
"correctement définis."

#: umc/python/diagnostic/plugins/51_hostname_check.py:77
#, python-brace-format
msgid "Please refer to {rfc1123} for the syntax of host names."
msgstr ""

#: umc/python/diagnostic/plugins/20_check_nameservers.py:220
#, fuzzy, python-brace-format
msgid "Please refer to {sdb} for further information."
msgstr ""
"Veuillez vérifier « /var/log/auth.log » sur le serveur distant pour plus "
"d'informations."

#: umc/python/diagnostic/plugins/01_ssh_connection.py:69
#, python-format
msgid ""
"Please repair the host key of the remote server in /root/.ssh/known_hosts on "
"%(fqdn)s."
msgstr ""
"Veuillez réparer la clé d'hôte du serveur distant dans « /root/.ssh/"
"known_hosts » pour %(fqdn)s."

#: umc/python/diagnostic/plugins/00_check_server_password.py:117
#, python-brace-format
msgid "Please see {sdb} for more information."
msgstr ""

#: umc/python/diagnostic/plugins/23_check_update_sites.py:84
#, python-brace-format
msgid "Please see {sdb} for troubleshooting DNS problems."
msgstr ""

#: umc/python/diagnostic/plugins/02_certificate_check.py:293
#, python-brace-format
msgid "Please see {sdb} on how to renew certificates."
msgstr ""

#: umc/python/diagnostic/plugins/12_proxy.py:14
msgid "Proxy server failure"
msgstr "Échec du serveur mandataire"

#: umc/python/diagnostic/plugins/51_hostname_check.py:47
msgid "RFC 1123 - 2.1 Host Names and Numbers"
msgstr ""

#: umc/python/diagnostic/plugins/54_sources_list_check.py:97
msgid "Regenerate sources.list"
msgstr ""

#: umc/python/diagnostic/plugins/60_old_schema_registration.py:84
msgid "Register Schema files"
msgstr ""

#: umc/python/diagnostic/plugins/22_kdc_service.py:373
msgid "Reset kerberos/kdc to 127.0.0.1"
msgstr ""

#: umc/python/diagnostic/plugins/40_samba_tool_dbcheck.py:74
msgid "Run `samba-tool dbcheck --fix --cross-ncs --yes`"
msgstr ""

#: umc/python/diagnostic/plugins/43_connectors4_rejects.py:42
msgid "S4 Connector rejects"
msgstr ""

#: umc/python/diagnostic/plugins/43_connectors4_rejects.py:119
#, python-brace-format
msgid "S4 DN: {s4}, UCS DN: {ucs}"
msgstr ""

#: umc/python/diagnostic/plugins/43_connectors4_rejects.py:116
msgid "S4 rejected:"
msgstr ""

#: umc/python/diagnostic/plugins/04_saml_certificate_check.py:53
#, fuzzy
msgid "SAML certificate verification failed!"
msgstr "Échec de l'authentification à la machine"

#: umc/python/diagnostic/plugins/01_ssh_connection.py:18
msgid "SSH connection to UCS server failed!"
msgstr "Échec de la connexion SSH au serveur UCS !"

#: umc/python/diagnostic/plugins/45_heimdal_on_samba4_dc.py:46
msgid "Samba 4 KDC running."
msgstr ""

#: umc/python/diagnostic/plugins/32_security_limits.py:26
msgid "Samba4 max open files - Univention Help"
msgstr ""

#: umc/python/diagnostic/plugins/32_security_limits.py:14
msgid "Security limits exceeded"
msgstr "Limites de sécurité atteintes"

#: umc/python/diagnostic/plugins/21_check_join_status.py:60
#, python-brace-format
msgid "See {erroranalysis} or run the join-scripts via {join}."
msgstr ""

#: umc/python/diagnostic/plugins/00_check_server_password.py:174
#, python-brace-format
msgid "See {sdb} for information on manual server password change."
msgstr ""

#: umc/python/diagnostic/plugins/57_univention_server_role_windows.py:42
msgid "Server Role Windows"
msgstr ""

#: umc/python/diagnostic/plugins/00_check_server_password.py:181
msgid "Set server/password/change=True"
msgstr ""

#: umc/python/diagnostic/plugins/00_check_server_password.py:187
msgid "Set server/password/interval=21"
msgstr ""

#: umc/python/diagnostic/plugins/56_univention_types.py:15
msgid ""
"Several services rely on the attribute \"univentionObjectType\" to search "
"and identify objects in LDAP."
msgstr ""

#: umc/python/diagnostic/plugins/57_univention_server_role_windows.py:44
msgid ""
"Several services rely on the attribute \"univentionServerRole\" to search "
"and identify objects in OpenLDAP."
msgstr ""

#: umc/python/diagnostic/plugins/30_disk_usage.py:130
msgid "Some disks are nearly full:"
msgstr ""

#: umc/python/diagnostic/__init__.py:297
msgid "Test again"
msgstr "Tester à nouveau"

#: umc/python/diagnostic/plugins/58_check_memberOf.py:41
msgid ""
"The \"memberOf\" group membership attribute is not available in the LDAP "
"server on this host. This feature is activated by default in new "
"installations since UCS version 4.3-0, and serveral services depend on it. "
"This feature will be a prerequisite in future UCS releases. You may want to "
"consider activating the memberOf feature for the LDAP server according to:"
msgstr ""

#: umc/python/diagnostic/plugins/43_connectors4_rejects.py:97
msgid ""
"The UCR variable {variable!r} is unset, but necessary for the S4 Connector."
msgstr ""

#: umc/python/diagnostic/plugins/04_saml_certificate_check.py:99
msgid "The certificate of the SAML identity provider does not match."
msgstr ""

#: umc/python/diagnostic/plugins/04_saml_certificate_check.py:120
msgid "The certificate of the SAML service provider does not match."
msgstr ""

#: umc/python/diagnostic/plugins/21_check_join_status.py:41
msgid "The check for the join status was succsesful."
msgstr ""

#: umc/python/diagnostic/plugins/54_sources_list_check.py:103
msgid "The error might be fixable by regenerating the sources.list."
msgstr ""

#: umc/python/diagnostic/plugins/50_check_ucr_templates.py:55
msgid "The files should be checked for differences."
msgstr ""

#: umc/python/diagnostic/plugins/23_check_update_sites.py:80
msgid "The following FQDNs were not resolvable:"
msgstr ""

#: umc/python/diagnostic/plugins/22_kdc_service.py:347
msgid "The following KDCs were unreachable: {}"
msgstr ""

#: umc/python/diagnostic/plugins/50_check_ucr_templates.py:53
msgid "The following UCR files are modified locally."
msgstr ""

#: umc/python/diagnostic/plugins/60_old_schema_registration.py:82
msgid "The following files seem to be registered in the old way:"
msgstr ""

#: umc/python/diagnostic/plugins/01_ssh_connection.py:65
msgid ""
"The following list shows the affected remote servers and the reason for the "
"failed ssh connection:"
msgstr ""
"La liste suivante affiche les serveurs distants affectés et la raison de "
"l'échec de la connexion SSH :"

#: umc/python/diagnostic/plugins/51_hostname_check.py:75
#, python-brace-format
msgid "The following non-compliant hostnames have been found: {hostnames}."
msgstr ""

#: umc/python/diagnostic/plugins/10_gateway.py:13
#, python-format
msgid ""
"The gateway %r could not be reached. Please make sure the gateway and "
"related network settings are correctly configured by using the {setup:"
"network}."
msgstr ""
"Impossible d'atteindre la passerelle %r. Veuillez vous assurer que la "
"passerelle et les réglages réseaux associés soient configurés correctement "
"en utilisant {setup:network}."

#: umc/python/diagnostic/plugins/12_proxy.py:71
msgid ""
"The hostname of the proxy could not be resolved. May check your DNS "
"configuration."
msgstr ""
"Impossible de résoudre le nom d'hôte du serveur mandataire. Veuillez "
"vérifier votre configuration DNS."

#: umc/python/diagnostic/plugins/32_security_limits.py:62
msgid "The limits have been adjusted to the suggested value."
msgstr "Les limites ont été adaptées à la valeur suggérée."

#: umc/python/diagnostic/plugins/55_user_migration.py:41
#, fuzzy, python-format
msgid "The migration failed: %s"
msgstr "Échec de l'authentification à la machine"

#: umc/python/diagnostic/plugins/11_nameserver.py:45
#, python-format
msgid "The nameserver %(nameserver)s (UCR variable %(var)r) is not responsive:"
msgstr ""
"Le serveur de noms %(nameserver)s (variable UCR %(var)r) n'est pas réactif :"

#: umc/python/diagnostic/plugins/53_package_status.py:13
#, python-format
msgid "The package status of %s packages is corrupt."
msgstr "Les états des paquetages %s sont corrompus."

#: umc/python/diagnostic/plugins/60_old_schema_registration.py:18
msgid ""
"The preferred way now is to register them in LDAP; this is less error prone "
"in situations like backup2master."
msgstr ""

#: umc/python/diagnostic/plugins/59_ldap_server_name.py:61
#, python-format, python-brace-format
msgid ""
"The primary LDAP Server of this System (UCR ldap/server/name) is set to the "
"Primary Directory Node of this UCS domain (%s).\n"
"Since this environment provides further LDAP Servers, we recommend a "
"different configuration to reduce the load on the Primary Directory Node.\n"
"Please see {sdb} for further information."
msgstr ""

#: umc/python/diagnostic/plugins/12_proxy.py:69
#, python-format
msgid ""
"The proxy host could not be reached. Make sure that hostname (%(hostname)r) "
"and port (%(port)r) are correctly set up."
msgstr ""
"Impossible d'atteindre le serveur mandataire. Veuillez vous assurer que le "
"nom d'hôte (%(hostname)r) et le port (%(port)r) sont correctement définis."

#: umc/python/diagnostic/plugins/12_proxy.py:87
#, python-format
msgid ""
"The proxy server is reachable but the HTTP response status code (%d) does "
"not indicate success."
msgstr ""
"Le serveur mandataire est accessible, mais le code d'état de la réponse HTTP "
"(%d) n'indique pas une réussite."

#: umc/python/diagnostic/plugins/60_old_schema_registration.py:97
#, fuzzy, python-format
msgid "The registration failed: %s"
msgstr "Échec de l'authentification à la machine"

#: umc/python/diagnostic/plugins/32_security_limits.py:17
msgid ""
"The security limits (e.g. for max_open_files) are currently not configured "
"properly."
msgstr ""
"Les limites de sécurité (par ex. pour « max_open_files ») ne sont pas pas "
"configurées correctement."

#: umc/python/diagnostic/plugins/12_proxy.py:73
#, python-format
msgid ""
"The server did not respond within %d seconds. Please check your network "
"configuration."
msgstr ""
"Le serveur n'a pas répondu dans les %d secondes. Veuillez vérifier votre "
"configuration réseau."

#: umc/python/diagnostic/plugins/01_ssh_connection.py:64
msgid "The ssh connection to at least one other UCS server failed. "
msgstr "Échec de la connexion SSH à au moins un autre serveur UCS."

#: umc/python/diagnostic/plugins/01_ssh_connection.py:68
msgid ""
"The ssh host key of the remote server has changed (maybe the host was "
"reinstalled). "
msgstr ""
"La clé d'hôte SSH du serveur distant a été modifiée (l'hôte a peut-être été "
"réinstallé)."

#: umc/python/diagnostic/plugins/10_gateway.py:31
msgid "There is no gateway configured."
msgstr ""

#: umc/python/diagnostic/plugins/12_proxy.py:15
msgid ""
"There was an error using the proxy server. The {setup:network} can be used "
"to change the proxy configuration.\n"
msgstr ""
"Erreur lors de l'utilisation du serveur mandataire. {setup:network} peut "
"être utilisé pour modifier la configuration du serveur mandataire.\n"

#: umc/python/diagnostic/plugins/57_univention_server_role_windows.py:85
#: umc/python/diagnostic/plugins/56_univention_types.py:50
msgid "These objects were found:"
msgstr ""

#: umc/python/diagnostic/plugins/32_security_limits.py:18
msgid ""
"This can cause several different serious problems (e.g. the login at samba "
"servers may be impossible, file operations (copy, move) on shares can fail, "
"etc.)"
msgstr ""
"Cela peut causer un certain nombre de problèmes importants (ex. : la "
"connexion aux serveurs Samba peut être impossible, les opérations sur les "
"fichiers (copie, déplacement) sur les partages peuvent échouer, etc.)"

#: umc/python/diagnostic/plugins/45_heimdal_on_samba4_dc.py:77
msgid ""
"This is a Samba 4 DC, but `samba-tool processes` reports no `kdc_server`."
msgstr ""

#: umc/python/diagnostic/plugins/52_mail_acl_sync.py:235
msgid "This is not necessarily a problem, if the the ACL got changed via IMAP."
msgstr ""

#: umc/python/diagnostic/plugins/45_heimdal_on_samba4_dc.py:78
msgid "This may be, because Heimdal KDC seems to be running."
msgstr ""

#: umc/python/diagnostic/plugins/45_heimdal_on_samba4_dc.py:79
msgid "This may be, because `kerberos/autostart` is not disabled."
msgstr ""

#: umc/python/diagnostic/plugins/51_hostname_check.py:76
msgid "This may lead to DNS problems."
msgstr ""

#: umc/python/diagnostic/plugins/03_check_notifier_replication.py:80
msgid "This might indicate an error or still processing transactions."
msgstr ""

#: umc/python/diagnostic/plugins/12_proxy.py:88
#, python-format
msgid ""
"This warning might be harmless. Nevertheless make sure the authentication "
"credentials (if any) are correct and the proxy server ACLs do not forbid "
"requests to %s."
msgstr ""
"Cet avertissement est peut-être sans danger. Veuillez cependant vous assurer "
"que les preuves d'identité (s'il y en a) sont correctes et que les ACL du "
"serveur mandataire n'interdisent pas les requêtes vers %s."

#: umc/python/diagnostic/plugins/43_connectors4_rejects.py:112
#, python-brace-format
msgid "UCS DN: {ucs}, S4 DN: {s4}, Filename: {fn}"
msgstr ""

#: umc/python/diagnostic/plugins/43_connectors4_rejects.py:109
msgid "UCS rejected:"
msgstr ""

#: umc/python/diagnostic/plugins/00_check_server_password.py:74
msgid "Unable to fix machine password on {}"
msgstr ""

#: umc/python/diagnostic/plugins/03_check_notifier_replication.py:79
msgid "Univention Directory Notifier ID and the locally stored version differ."
msgstr ""

#: umc/python/diagnostic/plugins/43_connectors4_rejects.py:91
msgid "Univention S4 Connector is not installed."
msgstr ""

#: umc/python/diagnostic/plugins/20_check_nameservers.py:54
msgid "Univention Support Database - Bind: zone transfer failed"
msgstr ""

#: umc/python/diagnostic/plugins/59_ldap_server_name.py:21
msgid ""
"Univention Support Database - Change the primary LDAP Server to redistribute "
"the server load"
msgstr ""

#: umc/python/diagnostic/plugins/23_check_update_sites.py:47
msgid ""
"Univention Support Database - DNS Server on Directory Node does not resolve "
"external names"
msgstr ""

#: umc/python/diagnostic/plugins/43_connectors4_rejects.py:47
msgid "Univention Support Database - How to deal with s4-connector rejects"
msgstr ""

#: umc/python/diagnostic/plugins/00_check_server_password.py:57
msgid "Univention Support Database - Manually trigger server password change"
msgstr ""

#: umc/python/diagnostic/plugins/02_certificate_check.py:56
msgid "Univention Support Database - Renewing the TLS/SSL certificates"
msgstr ""

#: umc/python/diagnostic/plugins/03_check_notifier_replication.py:47
msgid "Univention Support Database - Troubleshooting: Listener-/Notifier"
msgstr ""

#: umc/python/diagnostic/plugins/50_check_ucr_templates.py:54
msgid "Updated versions will be named FILENAME.dpkg-*."
msgstr ""

#: umc/python/diagnostic/plugins/55_user_migration.py:12
msgid "User objects which are not migrated"
msgstr ""

#: umc/python/diagnostic/plugins/44_well_known_sid_check.py:85
msgid ""
"User or group with SID {sid} has name {actual!r}, but should be {expected!r}."
msgstr ""

#: umc/python/diagnostic/plugins/44_well_known_sid_check.py:75
msgid ""
"User or group with name {name!r} has sid {actual_sid}, but should be {sid}."
msgstr ""

#: umc/python/diagnostic/plugins/55_user_migration.py:15
msgid ""
"When a user object is created by a system which is not yet on UCS 4.3 it "
"will have the old format. These user objects need to migrated again."
msgstr ""

#: umc/python/diagnostic/plugins/55_user_migration.py:14
msgid ""
"With UCS 4.3 the LDAP format of user objects changed. After upgrading the "
"Primary Directory Node all user objects are migrated into the new format."
msgstr ""

#: umc/python/diagnostic/plugins/40_samba_tool_dbcheck.py:84
msgid "You can run `samba-tool dbcheck --fix` to fix the issue."
msgstr ""

#: umc/python/diagnostic/plugins/30_disk_usage.py:137
msgid "You have configured some high log levels."
msgstr ""

#: umc/python/diagnostic/plugins/53_package_status.py:14
#, fuzzy
msgid ""
"You may log in to the system as root via ssh and run the command \"dpkg --"
"configure -a\" as an attempt to correct the packages status."
msgstr ""
"Connectez-vous au système en tant que super utilisateur par le biais de SSH "
"et exécutez la commande « dpkg --configure -a » afin de corriger l'état des "
"paquetages."

#: umc/python/diagnostic/plugins/30_disk_usage.py:114
msgid "You may want to move /var/log to another disk or storage."
msgstr ""

#: umc/python/diagnostic/plugins/30_disk_usage.py:116
msgid "You may want to move the local repository to another server."
msgstr ""

#: umc/python/diagnostic/plugins/30_disk_usage.py:137
#, python-brace-format
msgid "You may want to reset them via {ucr}."
msgstr ""

#: umc/python/diagnostic/plugins/45_heimdal_on_samba4_dc.py:80
#, python-brace-format
msgid "You may want to stop Heimdal KDC and restart Samba via {services}"
msgstr ""

#: umc/python/diagnostic/plugins/30_disk_usage.py:112
msgid "You may want to uninstall software via {appcenter:appcenter}."
msgstr ""

#: umc/python/diagnostic/plugins/46_kerberos_ddns_update.py:63
#, python-brace-format
msgid "`kinit` for principal {princ} with keytab {tab} failed."
msgstr ""

#: umc/python/diagnostic/plugins/46_kerberos_ddns_update.py:65
#, python-brace-format
msgid "`kinit` for principal {princ} with password file {file} failed."
msgstr ""

#: umc/python/diagnostic/plugins/46_kerberos_ddns_update.py:76
#, python-brace-format
msgid "`nsupdate` check for domain {domain} failed ({details})."
msgstr ""

#: umc/python/diagnostic/plugins/40_samba_tool_dbcheck.py:80
msgid "`samba-tool dbcheck` found an error in the local AD database."
msgstr ""

#: umc/python/diagnostic/plugins/40_samba_tool_dbcheck.py:89
msgid "`samba-tool dbcheck` found no errors in the local AD database."
msgstr ""

#: umc/python/diagnostic/plugins/41_samba_tool_showrepl.py:148
msgid "`samba-tool drs showrepl` returned a problem with the replication."
msgstr ""

#: umc/python/diagnostic/plugins/02_certificate_check.py:55
msgid "http://sdb.univention.de/1183"
msgstr ""

#: umc/python/diagnostic/plugins/20_check_nameservers.py:53
msgid "http://sdb.univention.de/1273"
msgstr ""

#: umc/python/diagnostic/plugins/23_check_update_sites.py:46
msgid "http://sdb.univention.de/1298"
msgstr ""

#: umc/python/diagnostic/plugins/21_check_join_status.py:44
msgid ""
"https://docs.software-univention.de/manual-4.4.html#domain:listenernotifier:"
"erroranalysis"
msgstr ""

#: umc/python/diagnostic/plugins/58_check_memberOf.py:44
msgid ""
"https://help.univention.com/t/memberof-attribute-group-memberships-of-user-"
"and-computer-objects/6439"
msgstr ""

#: umc/python/diagnostic/plugins/32_security_limits.py:25
msgid "https://help.univention.com/t/samba4-max-open-files/1758"
msgstr ""

#: umc/python/diagnostic/plugins/51_hostname_check.py:46
msgid "https://tools.ietf.org/html/rfc1123#section-2"
msgstr ""

#: umc/python/diagnostic/plugins/43_connectors4_rejects.py:111
#: umc/python/diagnostic/plugins/43_connectors4_rejects.py:118
msgid "not found"
msgstr ""

#: umc/python/diagnostic/plugins/22_kdc_service.py:103
msgid "ph "
msgstr ""

#: umc/python/diagnostic/plugins/22_kdc_service.py:364
msgid "samba/interfaces does not contain lo, 127.0.0.1 or 0.0.0.0."
msgstr ""

#: umc/python/diagnostic/plugins/53_package_status.py:31
msgid "some"
msgstr "certains"
